### 九 错误处理

当未设置错误处理函数时，PHP 会根据配置处理出现的错误。 php.ini 中 [`error_reporting`](https://www.php.net/manual/zh/errorfunc.configuration.php#ini.error-reporting) 的配置或者是运行时调用 [error_reporting()](https://www.php.net/manual/zh/function.error-reporting.php) 控制了哪些错误需要报告，哪些错误需要自动忽略。 由于有些错误会在运行用户脚本前就可能出现，所以强烈推荐用配置指令来设置。

在开发环境里为了发现并修复 PHP 产生的问题， 应该总是把 [`error_reporting`](https://www.php.net/manual/zh/errorfunc.configuration.php#ini.error-reporting) 设置为 **`E_ALL`**。 在生产环境里，用户可能为了降低信息的详细程度， 想要将它设置为类似 `E_ALL & ~E_NOTICE & ~E_DEPRECATED`， 但很多情况下 **`E_ALL`** 也同样适用，这样可以更早地警告潜在问题。

PHP 对这些错误的处理方式，取决于两个更深的 php.ini 指令。 [`display_errors`](https://www.php.net/manual/zh/errorfunc.configuration.php#ini.display-errors) 控制了是否要将错误作为脚本输出的一部分显示。 在生产环境里应该禁用，因为可能包含类似数据库密码这样的敏感信息， 而在开发环境中应该启用，能确保立即报告问题。

PHP 不仅能显示错误，还可以开启 [`log_errors`](https://www.php.net/manual/zh/errorfunc.configuration.php#ini.log-errors) 指令来记录错误日志。它能根据 [`error_log`](https://www.php.net/manual/zh/errorfunc.configuration.php#ini.error-log) 的设置，记录任意错误到文件或者 syslog。 特别适用于生产环境，用户可以记录发生的错误，并根据这些错误生成报告。



### 十 异常

如果抛出异常的函数作用域内没有 [`catch`](https://www.php.net/manual/zh/language.exceptions.php#language.exceptions.catch) 块，异常会沿调用栈“向上冒泡”，直到找到匹配的 [`catch`](https://www.php.net/manual/zh/language.exceptions.php#language.exceptions.catch) 块。沿途会执行所有遇到的 [`finally`](https://www.php.net/manual/zh/language.exceptions.php#language.exceptions.finally) 块。在没有设置全局异常处理程序时，如果调用栈向上都没有遇到匹配的 [`catch`](https://www.php.net/manual/zh/language.exceptions.php#language.exceptions.catch)，程序会抛出 fatal 错误并终止。

抛出的对象必须是 [`instanceof`](https://www.php.net/manual/zh/language.operators.type.php) [Throwable](https://www.php.net/manual/zh/class.throwable.php)。尝试抛出其他对象会导致 PHP Fatal 错误。



[`finally`](https://www.php.net/manual/zh/language.exceptions.php#language.exceptions.finally) 代码块可以放在 [`catch`](https://www.php.net/manual/zh/language.exceptions.php#language.exceptions.catch) 之后，或者直接代替它。 无论是否抛出了异常，在 [`try`](https://www.php.net/manual/zh/language.exceptions.php) 和 [`catch`](https://www.php.net/manual/zh/language.exceptions.php#language.exceptions.catch) 之后、在执行后续代码之前， 放在 [`finally`](https://www.php.net/manual/zh/language.exceptions.php#language.exceptions.finally) 里的代码总是会执行。

值得注意的是 [`finally`](https://www.php.net/manual/zh/language.exceptions.php#language.exceptions.finally) 和 [`return`](https://www.php.net/manual/zh/function.return.php) 语句之间存在相互影响。 如果在 [`try`](https://www.php.net/manual/zh/language.exceptions.php) 或 [`catch`](https://www.php.net/manual/zh/language.exceptions.php#language.exceptions.catch) 里遇到 [`return`](https://www.php.net/manual/zh/function.return.php)，仍然会执行 [`finally`](https://www.php.net/manual/zh/language.exceptions.php#language.exceptions.finally) 里的代码。 而且，遇到 [`return`](https://www.php.net/manual/zh/function.return.php) 语句时，会先执行 [`finally`](https://www.php.net/manual/zh/language.exceptions.php#language.exceptions.finally) 再返回结果。 此外，如果 [`finally`](https://www.php.net/manual/zh/language.exceptions.php#language.exceptions.finally) 里也包含了 [`return`](https://www.php.net/manual/zh/function.return.php) 语句，将返回 [`finally`](https://www.php.net/manual/zh/language.exceptions.php#language.exceptions.finally) 里的值。



```php
<?php
function inverse($x) {
    if (!$x) {
        throw new Exception('Division by zero.');
    }
    return 1/$x;
}

try {
    echo inverse(5) . "\n";
    echo inverse(0) . "\n";
} catch (Exception $e) {
    echo 'Caught exception: ',  $e->getMessage(), "\n";
}

// 继续执行
echo "Hello World\n";
?>
```

输出：

```
0.2
Caught exception: Division by zero.
Hello World
```



```php
<?php
function inverse($x) {
    if (!$x) {
        throw new Exception('Division by zero.');
    }
    return 1/$x;
}

try {
    echo inverse(5) . "\n";
} catch (Exception $e) {
    echo 'Caught exception: ',  $e->getMessage(), "\n";
} finally {
    echo "First finally.\n";
}

try {
    echo inverse(0) . "\n";
} catch (Exception $e) {
    echo 'Caught exception: ',  $e->getMessage(), "\n";
} finally {
    echo "Second finally.\n";
}

// 继续执行
echo "Hello World\n";
?>
```

输出：

```
0.2
First finally.
Caught exception: Division by zero.
Second finally.
Hello World
```



```php
<?php

function test() {
    try {
        throw new Exception('foo');
    } catch (Exception $e) {
        return 'catch';
    } finally {
        return 'finally';
    }
}

echo test();
?>
```

`finally` 依然会输出。



#### 1. 全局异常处理程序

当允许异常冒泡到全局作用域时，它可以被全局异常处理器捕获到。 `set_exception_handler()` 可以设置一个函数，在没有调用其他块时代替 `catch`。 在本质上，实现的效果等同于整个程序被 `try` - `catch` 包裹起来， 而该函数就是 `catch`。



#### 2. 扩展异常处理类

```php
<?php
class Exception implements Throwable
{
    protected $message = 'Unknown exception';   // 异常信息
    private   $string;                          // __toString 的缓存
    protected $code = 0;                        // 用户自定义异常错误码
    protected $file;                            // 发生异常的源文件名
    protected $line;                            // 发生异常的源代码行号
    private   $trace;                           // backtrace
    private   $previous;                        // 如果是嵌套异常，则是之前的 exception

    public function __construct($message = '', $code = 0, Throwable $previous = null);

    final private function __clone();           // 禁止克隆异常。

    final public  function getMessage();        // 异常信息
    final public  function getCode();           // 异常错误码
    final public  function getFile();           // 发生异常的源文件名
    final public  function getLine();           // 发生异常的源代码行号
    final public  function getTrace();          // backtrace() 数组
    final public  function getPrevious();       // 之前的 exception
    final public  function getTraceAsString();  // 已格成化成字符串的 getTrace() 信息

    // Overrideable
    public function __toString();               // 可输出的格式化后的字符串
}
?>
```

如果使用自定义的类来扩展内置异常处理类，并且要重新定义[构造函数](https://www.php.net/manual/zh/language.oop5.decon.php)的话，建议同时调用 `parent::__construct()` 来确保所有的变量已赋值。当对象要输出字符串的时候，可以重载 `__toString()` 并自定义输出的样式。

> 不能 复制 `Exception` 对象。尝试对 `clone` `Exception` 会导致 `fatal` `E_ERROR` 错误。

```php
<?php
/**
 * 自定义一个异常处理类
 */
class MyException extends Exception
{
    // 重定义构造器使 message 变为必须被指定的属性
    public function __construct($message, $code = 0, Throwable $previous = null) {
        // 这里写用户的代码

        // 确保所有变量都被正确赋值
        parent::__construct($message, $code, $previous);
    }

    // 自定义字符串输出的格式
    public function __toString() {
        return __CLASS__ . ": [{$this->code}]: {$this->message}\n";
    }

    public function customFunction() {
        echo "A custom function for this type of exception\n";
    }
}


/**
 * 创建一个类，测试该 exception 类
 */
class TestException
{
    public $var;

    const THROW_NONE    = 0;
    const THROW_CUSTOM  = 1;
    const THROW_DEFAULT = 2;

    function __construct($avalue = self::THROW_NONE) {

        switch ($avalue) {
            case self::THROW_CUSTOM:
                // 抛出自定义异常
                throw new MyException('1 is an invalid parameter', 5);
                break;

            case self::THROW_DEFAULT:
                // 抛出默认的异常
                throw new Exception('2 is not allowed as a parameter', 6);
                break;

            default: 
                // 没有异常的情况下，创建一个对象
                $this->var = $avalue;
                break;
        }
    }
}


// 例子 1
try {
    $o = new TestException(TestException::THROW_CUSTOM);
} catch (MyException $e) {      // 捕获异常
    echo "Caught my exception\n", $e;
    $e->customFunction();
} catch (Exception $e) {        // 被忽略
    echo "Caught Default Exception\n", $e;
}

// 继续执行后续代码
var_dump($o); // Null
echo "\n\n";


// 例子 2
try {
    $o = new TestException(TestException::THROW_DEFAULT);
} catch (MyException $e) {      //  不能匹配异常的种类，被忽略
    echo "Caught my exception\n", $e;
    $e->customFunction();
} catch (Exception $e) {        // 捕获异常
    echo "Caught Default Exception\n", $e;
}

// 执行后续代码
var_dump($o); // Null
echo "\n\n";


// 例子 3
try {
    $o = new TestException(TestException::THROW_CUSTOM);
} catch (Exception $e) {        // 捕获异常
    echo "Default Exception caught\n", $e;
}

// 执行后续代码
var_dump($o); // Null
echo "\n\n";


// 例子 4
try {
    $o = new TestException();
} catch (Exception $e) {        // 没有异常，被忽略
    echo "Default Exception caught\n", $e;
}

// 执行后续代码
var_dump($o); // TestException
echo "\n\n";
?>
```



